Workbook

Sheet 00 CISC Dashboard
A1: M | C1: CHIEF INVESTMENT STEWARD CONSOLE (CISC) | S1: ='01 Dashboard Controls'!B6 -> 46229 | V1: CISC-001 EXECUTIVE CONSOLE v1.0
C3: MANIFEST INSTITUTIONAL INVESTMENT SYSTEM
A5: 1 EXECUTIVE STATUS | C5: MANIFEST COMPOSITE ALIGNMENT GAUGE | K5: INSTITUTIONAL COMPASS | Q5: EXECUTIVE RECOMMENDATION
K6: ↗ | N6: CURRENT POSTURE | Q6: =IF('02 Decision Center'!B6="COMMITTEE ACTION REQUIRED","REVIEW IDENTIFIED DECISIONS","MAINTAIN PORTFOLIO CONSTRUCTION") -> MAINTAIN PORTFOLIO CONSTRUCTION
N9: ='01 Dashboard Controls'!B29 -> MAINTAIN STRATEGIC ALLOCATION
Q10: =IF('02 Decision Center'!B6="DATA UPDATE REQUIRED","Actual weights must be loaded before live rebalancing review.",IF('02 Decision Center'!B6="COMMITTEE ACTION REQUIRED","Committee review required. No automatic trades are authorized.","No structural changes recommended. Continue disciplined monitoring.")) -> Actual weights must be loaded before live rebalancing review.
C12: ='01 Dashboard Controls'!B27 -> 0.62 | F12: TREND | G12: ='01 Dashboard Controls'!B28 -> 0.04
F13: CONFIDENCE | G13: ='01 Dashboard Controls'!B11 -> 0.72 | K13: ="DISCIPLINED • BALANCED • "&'01 Dashboard Controls'!B30 -> DISCIPLINED • BALANCED • OPPORTUNISTIC
F14: PREVIOUS WEEK | G14: ='01 Dashboard Controls'!B10 -> 0.58 | Q14: ="NEXT REVIEW: "&TEXT('01 Dashboard Controls'!B12,"dddd, mmm d, yyyy") -> NEXT REVIEW: Monday, Jul 27, 2026
F15: CLASSIFICATION | G15: ='01 Dashboard Controls'!B31 -> GREEN / STRONG ALIGNMENT
A17: 2 PORTFOLIO HEALTH | C17: SLEEVE ALLOCATION | J17: TOP 10 HOLDINGS | Q17: ALLOCATION ALERTS
J18: Rank | K18: Holding | M18: Weight | N18: Role | P18: Conviction | Q18: Rank | R18: Holding | S18: Actual | T18: Target | U18: Variance | V18: Status | X18: Action
J19: ='99 Dashboard Data'!R2 -> 1 | K19: ='99 Dashboard Data'!S2 -> BRK.B | M19: ='99 Dashboard Data'!U2 -> 0.0302 | N19: ='99 Dashboard Data'!V2 -> Diversified capital-allocation anchor | P19: ='99 Dashboard Data'!W2 -> Unassigned | Q19: =IF(R19="","",'99 Dashboard Data'!R15) -> 1 | R19: =IF(OR('99 Dashboard Data'!S15=0,'99 Dashboard Data'!S15=""),"",'99 Dashboard Data'!S15) -> BRK.B | S19: =IF(R19="","",'99 Dashboard Data'!T15) -> 0 | T19: =IF(R19="","",'99 Dashboard Data'!U15) -> 0.0302 | U19: =IF(R19="","",'99 Dashboard Data'!V15) -> -0.0302 | V19: =IF(R19="","",'99 Dashboard Data'!W15) -> Not entered | X19: =IF(R19="","",'99 Dashboard Data'!X15) -> Enter actual weight
J20: ='99 Dashboard Data'!R3 -> 2 | K20: ='99 Dashboard Data'!S3 -> COST | M20: ='99 Dashboard Data'!U3 -> 0.0302 | N20: ='99 Dashboard Data'!V3 -> Consumer-resilience anchor | P20: ='99 Dashboard Data'!W3 -> Unassigned | Q20: =IF(R20="","",'99 Dashboard Data'!R16) -> 2 | R20: =IF(OR('99 Dashboard Data'!S16=0,'99 Dashboard Data'!S16=""),"",'99 Dashboard Data'!S16) -> COST | S20: =IF(R20="","",'99 Dashboard Data'!T16) -> 0 | T20: =IF(R20="","",'99 Dashboard Data'!U16) -> 0.0302 | U20: =IF(R20="","",'99 Dashboard Data'!V16) -> -0.0302 | V20: =IF(R20="","",'99 Dashboard Data'!W16) -> Not entered | X20: =IF(R20="","",'99 Dashboard Data'!X16) -> Enter actual weight
J21: ='99 Dashboard Data'!R4 -> 3 | K21: ='99 Dashboard Data'!S4 -> JNJ | M21: ='99 Dashboard Data'!U4 -> 0.0302 | N21: ='99 Dashboard Data'!V4 -> Healthcare and life-sciences resilience anchor | P21: ='99 Dashboard Data'!W4 -> Unassigned | Q21: =IF(R21="","",'99 Dashboard Data'!R17) -> 3 | R21: =IF(OR('99 Dashboard Data'!S17=0,'99 Dashboard Data'!S17=""),"",'99 Dashboard Data'!S17) -> JNJ | S21: =IF(R21="","",'99 Dashboard Data'!T17) -> 0 | T21: =IF(R21="","",'99 Dashboard Data'!U17) -> 0.0302 | U21: =IF(R21="","",'99 Dashboard Data'!V17) -> -0.0302 | V21: =IF(R21="","",'99 Dashboard Data'!W17) -> Not entered | X21: =IF(R21="","",'99 Dashboard Data'!X17) -> Enter actual weight
J22: ='99 Dashboard Data'!R5 -> 4 | K22: ='99 Dashboard Data'!S5 -> MSFT | M22: ='99 Dashboard Data'!U5 -> 0.0302 | N22: ='99 Dashboard Data'!V5 -> Enterprise technology and AI platform anchor | P22: ='99 Dashboard Data'!W5 -> Unassigned | Q22: =IF(R22="","",'99 Dashboard Data'!R18) -> 4 | R22: =IF(OR('99 Dashboard Data'!S18=0,'99 Dashboard Data'!S18=""),"",'99 Dashboard Data'!S18) -> MSFT | S22: =IF(R22="","",'99 Dashboard Data'!T18) -> 0 | T22: =IF(R22="","",'99 Dashboard Data'!U18) -> 0.0302 | U22: =IF(R22="","",'99 Dashboard Data'!V18) -> -0.0302 | V22: =IF(R22="","",'99 Dashboard Data'!W18) -> Not entered | X22: =IF(R22="","",'99 Dashboard Data'!X18) -> Enter actual weight
J23: ='99 Dashboard Data'!R6 -> 5 | K23: ='99 Dashboard Data'!S6 -> AVGO | M23: ='99 Dashboard Data'!U6 -> 0.0302 | N23: ='99 Dashboard Data'!V6 -> Semiconductor and infrastructure-software compounder | P23: ='99 Dashboard Data'!W6 -> Unassigned | Q23: =IF(R23="","",'99 Dashboard Data'!R19) -> 5 | R23: =IF(OR('99 Dashboard Data'!S19=0,'99 Dashboard Data'!S19=""),"",'99 Dashboard Data'!S19) -> AVGO | S23: =IF(R23="","",'99 Dashboard Data'!T19) -> 0 | T23: =IF(R23="","",'99 Dashboard Data'!U19) -> 0.0302 | U23: =IF(R23="","",'99 Dashboard Data'!V19) -> -0.0302 | V23: =IF(R23="","",'99 Dashboard Data'!W19) -> Not entered | X23: =IF(R23="","",'99 Dashboard Data'!X19) -> Enter actual weight
J24: ='99 Dashboard Data'!R7 -> 6 | K24: ='99 Dashboard Data'!S7 -> LLY | M24: ='99 Dashboard Data'!U7 -> 0.0302 | N24: ='99 Dashboard Data'!V7 -> Healthcare innovation compounder | P24: ='99 Dashboard Data'!W7 -> Unassigned | Q24: =IF('99 Dashboard Data'!B61>0,'99 Dashboard Data'!B61&" actual weights are not loaded. Allocation alerts are not yet live.",IF('99 Dashboard Data'!B62=0,"All positions are within certified bands.","Committee review required for "&'99 Dashboard Data'!B62&" allocation-band exceptions.")) -> 47 actual weights are not loaded. Allocation alerts are not yet live.
J25: ='99 Dashboard Data'!R8 -> 7 | K25: ='99 Dashboard Data'!S8 -> CME | M25: ='99 Dashboard Data'!U8 -> 0.0302 | N25: ='99 Dashboard Data'!V8 -> Market infrastructure and derivatives exchange | P25: ='99 Dashboard Data'!W8 -> Unassigned
J26: ='99 Dashboard Data'!R9 -> 8 | K26: ='99 Dashboard Data'!S9 -> LNG | M26: ='99 Dashboard Data'!U9 -> 0.0302 | N26: ='99 Dashboard Data'!V9 -> LNG export infrastructure | P26: ='99 Dashboard Data'!W9 -> Unassigned
J27: ='99 Dashboard Data'!R10 -> 9 | K27: ='99 Dashboard Data'!S10 -> VPU | M27: ='99 Dashboard Data'!U10 -> 0.0302 | N27: ='99 Dashboard Data'!V10 -> Utilities and defensive infrastructure ETF | P27: ='99 Dashboard Data'!W10 -> Unassigned | Q27: OUTSIDE BAND = REVIEW REQUIRED • NO AUTOMATIC TRADING
J28: ='99 Dashboard Data'!R11 -> 10 | K28: ='99 Dashboard Data'!S11 -> JEPI | M28: ='99 Dashboard Data'!U11 -> 0.0302 | N28: ='99 Dashboard Data'!V11 -> Diversified equity income and volatility moderation | P28: ='99 Dashboard Data'!W11 -> Unassigned
J29: ="RANKING BASIS: "&'99 Dashboard Data'!B65 -> RANKING BASIS: Target Weight
Q30: ="DATA COMPLETENESS: "&TEXT('99 Dashboard Data'!B64,"0%")&" | ACTUAL TOTAL: "&TEXT('99 Dashboard Data'!B63,"0.00%") -> DATA COMPLETENESS: 0% | ACTUAL TOTAL: 0.00%
J31: =IF('99 Dashboard Data'!B61>0,"Actual weights incomplete — displaying certified target-weight ranking.","Actual weights complete — displaying live position ranking.") -> Actual weights incomplete — displaying certified target-weight ranking.
A34: 3 RESEARCH INTELLIGENCE | C34: COMPANIES REQUIRING REVIEW | G34: EARNINGS THIS WEEK | K34: ZACKS RANK CHANGES | O34: MERRILL RESEARCH UPDATES | S34: MIAR UPDATES | V34: THESIS / CONVICTION REVIEWS
C36: =IF('03 Research Intelligence'!A7="","No entry loaded",'03 Research Intelligence'!A7&" — "&'03 Research Intelligence'!C7) -> No entry loaded | G36: =IF('03 Research Intelligence'!B19="","No entry loaded",TEXT('03 Research Intelligence'!A19,"m/d")&" "&'03 Research Intelligence'!B19&" — "&'03 Research Intelligence'!D19) -> No entry loaded | K36: =IF('03 Research Intelligence'!B31="","No entry loaded",'03 Research Intelligence'!B31&" #"&'03 Research Intelligence'!C31&" → #"&'03 Research Intelligence'!D31) -> No entry loaded | O36: =IF('03 Research Intelligence'!B43="","No entry loaded",'03 Research Intelligence'!B43&" — "&'03 Research Intelligence'!C43) -> No entry loaded | S36: =IF('03 Research Intelligence'!A55="","No entry loaded",'03 Research Intelligence'!A55&" — "&'03 Research Intelligence'!B55&" / "&'03 Research Intelligence'!F55) -> No entry loaded | V36: =IF('03 Research Intelligence'!A67="","No entry loaded",'03 Research Intelligence'!A67&" — "&'03 Research Intelligence'!D67) -> No entry loaded
G38: =IF('03 Research Intelligence'!B20="","No entry loaded",TEXT('03 Research Intelligence'!A20,"m/d")&" "&'03 Research Intelligence'!B20&" — "&'03 Research Intelligence'!D20) -> No entry loaded | K38: =IF('03 Research Intelligence'!B32="","No entry loaded",'03 Research Intelligence'!B32&" #"&'03 Research Intelligence'!C32&" → #"&'03 Research Intelligence'!D32) -> No entry loaded | O38: =IF('03 Research Intelligence'!B44="","No entry loaded",'03 Research Intelligence'!B44&" — "&'03 Research Intelligence'!C44) -> No entry loaded
C39: =IF('03 Research Intelligence'!A8="","No entry loaded",'03 Research Intelligence'!A8&" — "&'03 Research Intelligence'!C8) -> No entry loaded | S39: =IF('03 Research Intelligence'!A56="","No entry loaded",'03 Research Intelligence'!A56&" — "&'03 Research Intelligence'!B56&" / "&'03 Research Intelligence'!F56) -> No entry loaded | V39: =IF('03 Research Intelligence'!A68="","No entry loaded",'03 Research Intelligence'!A68&" — "&'03 Research Intelligence'!D68) -> No entry loaded
G40: =IF('03 Research Intelligence'!B21="","No entry loaded",TEXT('03 Research Intelligence'!A21,"m/d")&" "&'03 Research Intelligence'!B21&" — "&'03 Research Intelligence'!D21) -> No entry loaded | K40: =IF('03 Research Intelligence'!B33="","No entry loaded",'03 Research Intelligence'!B33&" #"&'03 Research Intelligence'!C33&" → #"&'03 Research Intelligence'!D33) -> No entry loaded | O40: =IF('03 Research Intelligence'!B45="","No entry loaded",'03 Research Intelligence'!B45&" — "&'03 Research Intelligence'!C45) -> No entry loaded
C42: =IF('03 Research Intelligence'!A9="","No entry loaded",'03 Research Intelligence'!A9&" — "&'03 Research Intelligence'!C9) -> No entry loaded | G42: =IF('03 Research Intelligence'!B22="","No entry loaded",TEXT('03 Research Intelligence'!A22,"m/d")&" "&'03 Research Intelligence'!B22&" — "&'03 Research Intelligence'!D22) -> No entry loaded | K42: =IF('03 Research Intelligence'!B34="","No entry loaded",'03 Research Intelligence'!B34&" #"&'03 Research Intelligence'!C34&" → #"&'03 Research Intelligence'!D34) -> No entry loaded | O42: =IF('03 Research Intelligence'!B46="","No entry loaded",'03 Research Intelligence'!B46&" — "&'03 Research Intelligence'!C46) -> No entry loaded | S42: =IF('03 Research Intelligence'!A57="","No entry loaded",'03 Research Intelligence'!A57&" — "&'03 Research Intelligence'!B57&" / "&'03 Research Intelligence'!F57) -> No entry loaded | V42: =IF('03 Research Intelligence'!A69="","No entry loaded",'03 Research Intelligence'!A69&" — "&'03 Research Intelligence'!D69) -> No entry loaded
A47: 4 COMMITTEE OPERATIONS | C47: PENDING ACTIONS | H47: MWIR STATUS | M47: OPERATIONAL CALENDAR | R47: CERTIFICATION STATUS | V47: STEWARD'S NOTEBOOK
H48: ='04 Committee Operations'!A25 -> MWIR | M48: =IF('04 Committee Operations'!B37="","No event loaded",IF('04 Committee Operations'!A37="","TBD",TEXT('04 Committee Operations'!A37,"m/d"))&" — "&'04 Committee Operations'!B37) -> 7/27 — Monday workflow | R48: ='04 Committee Operations'!A51&" — "&'04 Committee Operations'!B51&" / "&'04 Committee Operations'!E51 -> Chief Investment Steward Console — CISC-001 / v1.0 / Frozen | V48: =COUNTIF('04 Committee Operations'!N8:N17,"Open")+COUNTIF('04 Committee Operations'!N8:N17,"Planned")&" priorities" -> 5 priorities
C49: Open / Planned Actions | G49: ='99 Dashboard Data'!B67 -> 4
C50: Research Decisions | G50: ='99 Dashboard Data'!B66 -> 0 | M50: =IF('04 Committee Operations'!B38="","No event loaded",IF('04 Committee Operations'!A38="","TBD",TEXT('04 Committee Operations'!A38,"m/d"))&" — "&'04 Committee Operations'!B38) -> 7/27 — MWIR publication | R50: ='04 Committee Operations'!A52&" — "&'04 Committee Operations'!B52&" / "&'04 Committee Operations'!E52 -> Manifest Flagship Portfolio Definition File — MFPDF v1.0 / Certified
C51: Allocation Decisions | G51: ='99 Dashboard Data'!B62 -> 0 | H51: ="STATUS: "&'04 Committee Operations'!E25 -> STATUS: Planned | V51: =COUNTIF('04 Committee Operations'!N21:N30,"Open")+COUNTIF('04 Committee Operations'!N21:N30,"Pending Data")&" committee questions" -> 5 committee questions
C52: Committee Decisions | G52: ='02 Decision Center'!B13 -> 0 | M52: =IF('04 Committee Operations'!B39="","No event loaded",IF('04 Committee Operations'!A39="","TBD",TEXT('04 Committee Operations'!A39,"m/d"))&" — "&'04 Committee Operations'!B39) -> TBD — Monthly allocation review | R52: ='04 Committee Operations'!A53&" — "&'04 Committee Operations'!B53&" / "&'04 Committee Operations'!E53 -> Manifest Visual Design System — MVDS v1.0 / Frozen
C53: Actual Weights Missing | G53: ='99 Dashboard Data'!B61 -> 47 | H53: ="LAST PUBLISHED: "&TEXT('04 Committee Operations'!C25,"m/d/yyyy") -> LAST PUBLISHED: 7/25/2026
C54: Data Completeness | G54: ='99 Dashboard Data'!B64 -> 0 | M54: =IF('04 Committee Operations'!B40="","No event loaded",IF('04 Committee Operations'!A40="","TBD",TEXT('04 Committee Operations'!A40,"m/d"))&" — "&'04 Committee Operations'!B40) -> TBD — Quarterly engineering review | R54: ='04 Committee Operations'!A54&" — "&'04 Committee Operations'!B54&" / "&'04 Committee Operations'!E54 -> Manifest Founders Edition — v1.0 / Complete | V54: =COUNTIF('04 Committee Operations'!N34:N43,"Planned")+COUNTIF('04 Committee Operations'!N34:N43,"In Progress")&" long-term projects" -> 5 long-term projects
C55: Decision State | G55: ='02 Decision Center'!B6 -> DATA UPDATE REQUIRED | H55: ="NEXT DUE: "&TEXT('04 Committee Operations'!D25,"m/d/yyyy") -> NEXT DUE: 7/27/2026
...

Sheet 01 Dashboard Controls
A1: MANIFEST WORKBENCH — DASHBOARD CONTROLS
A3: CISC-001 | Founders Edition v1.0 | Blue/yellow cells are weekly operating inputs
A5: Control Field | B5: Operating Value
A6: Report Date | B6: 46229
A7: Console ID | B7: CISC-001
A8: Edition | B8: Founders Edition v1.0
A9: Data Status | B9: PROTOTYPE VALUES — LIVE INPUTS REQUIRED
A10: Previous Week Score | B10: 0.58
A11: Confidence | B11: 0.72
A12: Next Review | B12: 46230
A13: MWIR Status | B13: Planned / not yet published
A15: Composite Component | B15: Score (-1 to +1) | C15: Weight | D15: Contribution | F15: Gauge Zone | G15: Value
A16: Macro Regime | B16: 0.6 | C16: 0.15 | D16: =B16*C16 -> 0.09 | F16: Positive / Green | G16: 40
A17: Credit Conditions | B17: 0.55 | C17: 0.15 | D17: =B17*C17 -> 0.0825 | F17: Neutral / Yellow | G17: 20
A18: Liquidity & Policy | B18: 0.45 | C18: 0.1 | D18: =B18*C18 -> 0.045 | F18: Caution / Orange | G18: 20
A19: Market Breadth | B19: 0.65 | C19: 0.1 | D19: =B19*C19 -> 0.065 | F19: Risk / Red | G19: 20
A20: Earnings & Fundamentals | B20: 0.7 | C20: 0.15 | D20: =B20*C20 -> 0.105
A21: Valuation Discipline | B21: 0.4 | C21: 0.1 | D21: =B21*C21 -> 0.04
A22: Portfolio Alignment | B22: 0.75 | C22: 0.15 | D22: =B22*C22 -> 0.1125 | F22: Score Floor | G22: Score Ceiling | H22: Posture
A23: Research Conviction | B23: 0.8 | C23: 0.1 | D23: =B23*C23 -> 0.08 | F23: 0.5 | G23: 1 | H23: Maintain / Opportunistic
A24: TOTAL / COMPOSITE | C24: =SUM(C16:C23) -> 1 | D24: =SUM(D16:D23) -> 0.62 | F24: 0.1 | G24: 0.49 | H24: Maintain / Balanced
F25: -0.09 | G25: 0.09 | H25: Hold / Disciplined
A26: Derived Indicator | B26: Result | F26: -0.34 | G26: -0.1 | H26: Defensive / Selective
A27: Composite Alignment Score | B27: =D24 -> 0.62 | F27: -1 | G27: -0.35 | H27: Reduce Risk
A28: Weekly Change | B28: =B27-B10 -> 0.04 | F28: Thresholds change only by committee action. | H28: Thresholds change only by committee action.
A29: Current Posture | B29: =IF(B27>=0.10,"MAINTAIN STRATEGIC ALLOCATION",IF(B27>-0.10,"HOLD / MONITOR",IF(B27>-0.35,"DEFENSIVE TILT","REDUCE RISK"))) -> MAINTAIN STRATEGIC ALLOCATION
A30: Compass Bias | B30: =IF(B27>=0.50,"OPPORTUNISTIC",IF(B27>=0.10,"BALANCED",IF(B27>-0.10,"DISCIPLINED",IF(B27>-0.35,"DEFENSIVE","CAPITAL PRESERVATION")))) -> OPPORTUNISTIC
A31: Score Classification | B31: =IF(B27>=0.50,"GREEN / STRONG ALIGNMENT",IF(B27>=0.10,"GREEN / POSITIVE ALIGNMENT",IF(B27>-0.10,"YELLOW / NEUTRAL",IF(B27>-0.35,"ORANGE / CAUTION","RED / RISK REDUCTION")))) -> GREEN / STRONG ALIGNMENT
A32: Prototype Note | B32: Replace component scores and confidence in each weekly run.

Sheet 02 Decision Center
A1: MANIFEST DECISION CENTER
A3: What decisions are actually required this week?
A5: Decision Metric | B5: Current State | D5: Governance Rule | E5: Result | F5: Meaning
A6: Decision State | B6: =IF(B8>0,"DATA UPDATE REQUIRED",IF(B13>0,"COMMITTEE ACTION REQUIRED","NO COMMITTEE ACTION REQUIRED")) -> DATA UPDATE REQUIRED | D6: Committee Meeting | E6: =IF(B6="COMMITTEE ACTION REQUIRED","CONVENE COMMITTEE",IF(B6="DATA UPDATE REQUIRED","DEFER — COMPLETE DATA","NO MEETING REQUIRED")) -> DEFER — COMPLETE DATA | F6: Convene only when a decision is actually required.
A7: Data Completeness | B7: ='99 Dashboard Data'!B64 -> 0 | D7: Automatic Trading | E7: PROHIBITED | F7: Committee review precedes implementation.
A8: Missing Actual Weights | B8: ='99 Dashboard Data'!B61 -> 47 | D8: Current Weight Basis | E8: ='99 Dashboard Data'!B65 -> Target Weight | F8: Top holdings use actual weights only when all 47 are loaded.
A9: Allocation Decisions | B9: ='99 Dashboard Data'!B62 -> 0 | D9: Rebalance Policy | E9: Band-Based | F9: Outside-band positions are reviewed, not automatically traded.
A10: Research / Conviction Decisions | B10: ='99 Dashboard Data'!B66 -> 0 | D10: No-Action State | E10: AUTHORIZED | F10: Display when data are complete and no decisions remain.
A11: Manual Committee Decisions | B11: =COUNTIFS(J28:J47,"Yes",K28:K47,"Open")+COUNTIFS(J28:J47,"Yes",K28:K47,"In Review") -> 0
A12: Open Operating Actions | B12: ='99 Dashboard Data'!B67 -> 4
A13: Total Committee Decisions | B13: =SUM(B9:B11) -> 0
A14: Highest Priority | B14: =IF(B8>0,"Load current actual portfolio weights",IF(B9>0,"Review allocation-band exceptions",IF(B10>0,"Resolve research or conviction decisions",IF(B11>0,"Resolve manual committee decisions","Continue disciplined monitoring")))) -> Load current actual portfolio weights
A17: SYSTEM DECISION QUEUE
A18: ID | B18: Category | C18: Trigger | D18: Decision Required | E18: Recommended Action | F18: Authority | G18: Status | H18: Evidence | I18: Owner | J18: Due | K18: Notes
A19: DC-SYS-001 | B19: Data Integrity | C19: =IF($B$8>0,$B$8&" actual weights missing","Actual weights complete") -> 47 actual weights missing | D19: =IF($B$8>0,"Data update required","No data decision") -> Data update required | E19: Load actual weights in Certified Allocation column I | F19: Portfolio Operations | G19: =IF($B$8>0,"ACTION REQUIRED","READY") -> ACTION REQUIRED | H19: MFPDF actual-weight fields | I19: Portfolio Operations | J19: 46230 | K19: Blocks live allocation decisions
A20: DC-SYS-002 | B20: Allocation | C20: =$B$9&" allocation-band exceptions" -> 0 allocation-band exceptions | D20: =IF($B$9>0,"Committee allocation decision","No allocation decision") -> No allocation decision | E20: Review each band exception; add/trim only after committee review | F20: Stewardship Committee | G20: =IF($B$8>0,"PENDING DATA",IF($B$9>0,"DECISION REQUIRED","NO DECISION")) -> PENDING DATA | H20: Certified bands and actual weights | I20: Portfolio Engineering | K20: No automatic rebalancing
A21: DC-SYS-003 | B21: Research | C21: =$B$10&" research / conviction decisions" -> 0 research / conviction decisions | D21: =IF($B$10>0,"Committee research decision","No research decision") -> No research decision | E21: Resolve items marked Decision Required | F21: Research / Stewardship Committee | G21: =IF($B$10>0,"DECISION REQUIRED","NO DECISION") -> NO DECISION | H21: Research Intelligence workspace | I21: Research Division
A22: DC-SYS-004 | B22: Manual Decisions | C22: =$B$11&" manual committee decisions" -> 0 manual committee decisions | D22: =IF($B$11>0,"Committee decision","No manual decision") -> No manual decision | E22: Resolve open manual committee decisions | F22: Stewardship Committee | G22: =IF($B$11>0,"DECISION REQUIRED","NO DECISION") -> NO DECISION | H22: Manual Decision Register | I22: Chief Investment Steward
A23: DC-SYS-005 | B23: Publication | C23: MWIR scheduled | D23: No committee decision unless recommendation changes | E23: Complete institutional publication workflow | F23: Publication Division | G23: Operational | H23: Committee Operations | I23: Publication Division | J23: 46230
A26: MANUAL DECISION REGISTER
A27: ID | B27: Date Opened | C27: Category | D27: Decision | E27: Evidence | F27: Recommendation | G27: Authority | H27: Owner | I27: Due Date | J27: Requires Committee Decision? | K27: Status
A28: DC-001 | B28: 46229 | C28: Governance | D28: Freeze CISC-001 as the five-panel visual reference standard | E28: Approved console design plus Manifest Decision Center | F28: Frozen as CISC-001 Founders Edition v1.0 | G28: Chief Investment Steward | H28: Chief Investment Steward | I28: 46229 | J28: No | K28: Closed
A29: DC-002 | B29: 46229 | C29: Operations | D29: Establish Manifest Workbench on the certified MFPDF foundation | E29: Canonical 47-position Portfolio B workbook | F29: Implement workbench without altering certified target weights | G29: Chief Investment Steward | H29: Portfolio Operations | I29: 46229 | J29: No | K29: Closed
A30: DC-003 | B30: 46229 | C30: Data | D30: Load current actual portfolio weights | E30: Certified Allocation column I is blank | F30: Complete data update before live band review | G30: Portfolio Operations | H30: Portfolio Operations | I30: 46230 | J30: No | K30: Open

Sheet 03 Research Intelligence
A1: RESEARCH INTELLIGENCE WORKSPACE
A3: Populate only verified current research. The dashboard reads the first active entries from each section.
A5: COMPANIES REQUIRING REVIEW
A6: Symbol | B6: Company | C6: Reason | D6: Trigger | E6: Priority | F6: Due Date | G6: Status
A17: EARNINGS / EVENT CALENDAR
A18: Date | B18: Symbol | C18: Company | D18: Event | E18: Status
A29: ZACKS RANK CHANGES
A30: Date | B30: Symbol | C30: Prior Rank | D30: Current Rank | E30: Direction | F30: Notes
A41: MERRILL RESEARCH UPDATES
A42: Date | B42: Symbol | C42: Rating / Action | D42: Price Target Change | E42: Thesis Impact | F42: Source Reference | G42: Status
A53: MIAR UPDATES
A54: Symbol | B54: Review Type | C54: Last Updated | D54: Due Date | E54: Owner | F54: Status
A65: THESIS / CONVICTION REVIEWS
A66: Symbol | B66: Current Conviction | C66: Proposed Conviction | D66: Reason | E66: Due Date | F66: Authority | G66: Status

Sheet 04 Committee Operations
A1: COMMITTEE OPERATIONS & STEWARD'S NOTEBOOK
A3: Operating actions remain distinct from committee decisions. Use the explicit decision flag.
A5: ACTION REGISTER | J5: STEWARD'S NOTEBOOK
A6: ID | B6: Category | C6: Action | D6: Owner | E6: Due Date | F6: Priority | G6: Status | H6: Requires Committee Decision? | I6: Linked Record
A7: OP-001 | B7: Governance | C7: Freeze CISC-001 visual dashboard with five panels | D7: Chief Investment Steward | E7: 46229 | F7: High | G7: Completed | H7: No | I7: CISC-001 | J7: THIS WEEK'S PRIORITIES
A8: OP-002 | B8: Operations | C8: Establish Manifest Workbench from canonical MFPDF | D8: Portfolio Operations | E8: 46229 | F8: High | G8: Completed | H8: No | I8: CISC-001 | J8: 1 | K8: Load current actual portfolio weights | L8: Portfolio Operations | M8: 46230 | N8: Open
A9: OP-003 | B9: Data | C9: Load current actual portfolio weights | D9: Portfolio Operations | E9: 46230 | F9: High | G9: Open | H9: No | I9: DC-SYS-001 | J9: 2 | K9: Populate current research intelligence | L9: Research Division | M9: 46230 | N9: Open
A10: OP-004 | B10: Research | C10: Populate current research intelligence | D10: Research Division | E10: 46230 | F10: High | G10: Open | H10: No | I10: DC-SYS-003 | J10: 3 | K10: Publish next MWIR | L10: Publication Division | M10: 46230 | N10: Planned
A11: OP-005 | B11: Publication | C11: Publish next MWIR | D11: Publication Division | E11: 46230 | F11: High | G11: Planned | H11: No | I11: MWIR | J11: 4 | K11: Run Monte Carlo on canonical Portfolio B | L11: Portfolio Engineering | N11: Planned
A12: OP-006 | B12: Analytics | C12: Run Monte Carlo on canonical Portfolio B | D12: Portfolio Engineering | F12: Medium | G12: Planned | H12: No | I12: MFPDF v1.0 | J12: 5 | K12: Assign conviction tiers | L12: Stewardship Committee | N12: Planned
J20: QUESTIONS FOR COMMITTEE
J21: Q1 | K21: Are any actual weights outside certified bands? | L21: Current weights | M21: Portfolio Operations | N21: Pending Data
J22: Q2 | K22: Does MU require a conviction change? | L22: Current research | M22: Research Division | N22: Open
A23: PUBLICATION STATUS | J23: Q3 | K23: Are any holdings carrying a Zacks #4 rating? | L23: Current Zacks file | M23: Research Division | N23: Open
A24: Publication | B24: Latest Issue | C24: Last Published | D24: Next Due | E24: Status | F24: Owner | J24: Q4 | K24: Are new candidates eligible for MASR review? | L24: Candidate dossiers | M24: Research Division | N24: Open
A25: MWIR | B25: Week ending Jul. 24, 2026 | C25: 46228 | D25: 46230 | E25: Planned | F25: Publication Division | J25: Q5 | K25: Is any sleeve outside its target allocation? | L25: Current weights | M25: Portfolio Engineering | N25: Pending Data
A26: MOR | B26: MOR-001 | C26: 46223 | E26: Scheduled | F26: Publication Division
A27: MIRD | B27: Weekly risk dashboard | C27: 46228 | D27: 46230 | E27: Scheduled | F27: Risk Division
A28: MIPR | B28: Institutional portfolio review | E28: Not Started | F28: Portfolio Division
J33: LONG-TERM PROJECTS
J34: P1 | K34: Monte Carlo Enhancement | L34: Portfolio Engineering | M34: Institutional simulation engine | N34: In Progress
A35: OPERATIONAL CALENDAR | J35: P2 | K35: Advisor Handbook | L35: Manifest Academy | M35: Operating handbook | N35: Planned
A36: Date | B36: Event | C36: Cadence | D36: Authority | E36: Status | J36: P3 | K36: Client Presentation | L36: Publication Division | M36: Client-ready deck | N36: Planned
A37: 46230 | B37: Monday workflow | C37: Weekly | D37: Chief Investment Steward | E37: Scheduled | J37: P4 | K37: Casebook Development | L37: Manifest Academy | M37: Founders casebook | N37: Planned
A38: 46230 | B38: MWIR publication | C38: Weekly | D38: Publication Division | E38: Scheduled | J38: P5 | K38: Library Expansion Plan | L38: Editorial Board | M38: Master library integration | N38: In Progress
B39: Monthly allocation review | C39: Monthly | D39: Stewardship Committee | E39: TBD
B40: Quarterly engineering review | C40: Quarterly | D40: Portfolio Engineering | E40: TBD
B41: MOR publication | C41: Monthly | D41: Publication Division | E41: TBD
A49: CERTIFICATION REGISTER
A50: Record | B50: Version | C50: Certified / Frozen | D50: Review Cadence | E50: Status | F50: Authority
A51: Chief Investment Steward Console | B51: CISC-001 / v1.0 | C51: 46229 | D51: Event-driven | E51: Frozen | F51: Chief Investment Steward
A52: Manifest Flagship Portfolio Definition File | B52: MFPDF v1.0 | C52: 46223 | D52: Quarterly + material event | E52: Certified | F52: Stewardship Committee
A53: Manifest Visual Design System | B53: MVDS v1.0 | C53: 46223 | D53: Amendment only | E53: Frozen | F53: Publication Committee
A54: Manifest Founders Edition | B54: v1.0 | C54: 46222 | D54: Constitutional amendment only | E54: Complete | F54: Founding Authority

Sheet 05 Workbench Guide
A1: MANIFEST WORKBENCH — OPERATING GUIDE & FREEZE RECORD
A3: CISC-001 is the frozen visual foundation. MFPDF v1.0 remains the sole portfolio-allocation authority.
A5: Freeze Field | B5: Adopted Standard | C5: Status | D5: Operating Effect | F5: Workbook Authority | G5: Standard | H5: Status
A6: Visual Standard | B6: Chief Investment Steward Console (CISC-001) | C6: Frozen | D6: All future executive interfaces inherit this architecture. | F6: Canonical Portfolio | G6: Portfolio B / 47 positions | H6: MFPDF v1.0
A7: Edition | B7: Founders Edition v1.0 | C7: Frozen | D7: Changes require explicit amendment. | F7: Certified Target Total | G7: 100.00% | H7: Locked
A8: Panel 1 | B8: Executive Status | C8: Required | D8: Composite gauge, institutional compass and executive recommendation. | F8: Lower Band | G8: MAX(1.00%, 75% of target) | H8: Active
A9: Panel 2 | B9: Portfolio Health | C9: Required | D9: Sleeves, top holdings and allocation alerts. | F9: Upper Band | G9: MIN(4.00%, 125% of target) | H9: Active
A10: Panel 3 | B10: Research Intelligence | C10: Required | D10: Current research queue, MIAR and conviction maintenance. | F10: Automatic Trading | G10: Not authorized | H10: Prohibited
A11: Panel 4 | B11: Committee Operations | C11: Required | D11: Actions, publications, calendar, certifications and steward notebook. | F11: Committee Review | G11: Precedes implementation | H11: Required when triggered
A12: Panel 5 | B12: Manifest Decision Center | C12: Required | D12: Answers what decisions are actually required this week. | F12: Actual Weights | G12: User-entered | H12: Currently required
A15: Weekly Workflow | B15: Action | C15: Primary Sheet | D15: Control | F15: Color / Entry Convention | G15: Meaning | H15: Use
A16: 1 | B16: Update report date, score components and confidence | C16: 01 Dashboard Controls | D16: Blue/yellow input cells | F16: Blue text + yellow fill | G16: Hardcoded operating input | H16: Update each reporting cycle
A17: 2 | B17: Load all 47 actual portfolio weights | C17: Certified Allocation — column I | D17: Required before live band decisions | F17: Green text | G17: Link to another worksheet | H17: Do not overwrite
A18: 3 | B18: Assign conviction and research status | C18: Certified Allocation — columns M–N | D18: Used by top-holdings and research panels | F18: Black text | G18: Formula / calculation | H18: Do not hardcode over formula
... A20: 5 | B20: Review the Manifest Decision Center | C20: 02 Decision Center | D20: No-action state is valid and explicit | F20: Green status | G20: Aligned / no decision required | H20: Continue monitoring
A21: 6 | B21: Publish the MWIR and related dashboards | C21: 00 CISC Dashboard | D21: No automatic trading
A24: Operating Rule: the workbench is an executive decision-support interface. It does not modify the frozen portfolio merely because a band is breached, and it never authorizes automatic trades. The correct weekly output may be “NO COMMITTEE ACTION REQUIRED.”
A26: MOPS-003 RESEARCH OPERATING ADDENDUM — RCC-001 & RCC-002 INSTALLED
A27: Research Step | B27: Action | C27: Primary Sheet | D27: Control | F27: Authority | G27: Output | H27: Portfolio Effect
A28: 1 | B28: Enter one verified or pending signal per row | C28: 18 RCC-002 Evidence Ledger | D28: Unique Evidence ID | F28: Research Operations | G28: Auditable intake record | H28: None
A29: 2 | B29: Review materiality, reliability and routing | C29: 17 RCC-002 Control Center | D29: Verification and referral gates | F29: Research Committee | G29: MIAR / thesis / conviction / PEW referral | H29: Scenario only
A30: 3 | B30: Monitor research readiness and exceptions | C30: 16 RCC-001 Control Center | D30: RCC-001 executive aggregation | F30: Chief Investment Steward | G30: Decision queue | H30: No direct allocation authority

Sheet Executive Summary
A1: MANIFEST FLAGSHIP PORTFOLIO DEFINITION FILE
A2: Founders Edition Version 1.0 — Canonical Implementation Workbook
A4: Certification Field | B4: Value | D4: Executive Certification
A5: Canonical portfolio | B5: Portfolio B | D5: This workbook supersedes all prior preliminary allocation workbooks. It reconciles the 47-symbol Portfolio B export with the MQOC-006 empirical optimizer. The optimizer's 2.00% placeholder has been assigned to MMC, the sole Portfolio B symbol absent from the provisional weight file. No other target weight was changed.
A6: Total positions | B6: 47
A7: Equities | B7: 40
A8: ETFs | B8: 7
A9: Certified target total | B9: ='Certified Allocation'!F53 -> 1
A10: Rebalancing policy | B10: Band-based; review before trade
A12: Operating Rules
A13: Rule | B13: Standard
A14: Target allocation | B14: 100.00%
A15: Position minimum | B15: 1.00% lower-band floor
A16: Position maximum | B16: 4.00% upper-band cap
A17: Review trigger | B17: Actual weight outside allowable band; committee review precedes implementation

Sheet Certified Allocation
A1: Manifest Flagship Portfolio Definition File (MFPDF) — Founders Edition v1.0
A2: Certified Target Allocation Schedule | Canonical Portfolio B | 47 positions
A4: Production Sleeve | B4: Symbol | C4: Security | D4: Security Type | E4: Portfolio Role | F4: Target Weight | G4: Lower Band | H4: Upper Band | I4: Actual Weight (Input) | J4: Variance to Target | K4: Band Status | L4: Rebalancing Action | M4: Conviction Tier (Input) | N4: Research Status (Input)
A5: Strategic Anchors | B5: BRK.B | C5: Berkshire Hathaway Inc. Class B | D5: Equity | E5: Diversified capital-allocation anchor | F5: 0.0302 | G5: =MAX(1%,F5*75%) -> 0.02265 | H5: =MIN(4%,F5*125%) -> 0.03775 | J5: =IF(I5="","",I5-F5) | K5: =IF(I5="","Not entered",IF(I5<G5,"Below band",IF(I5>H5,"Above band","Within band"))) -> Not entered | L5: =IF(I5="","Enter actual weight",IF(I5<G5,"Review / Add",IF(I5>H5,"Review / Trim","No action"))) -> Enter actual weight | M5: Unassigned | N5: Current
A6: Strategic Anchors | B6: COST | C6: Costco Wholesale Corporation | D6: Equity | E6: Consumer-resilience anchor | F6: 0.0302 | G6: =MAX(1%,F6*75%) -> 0.02265 | H6: =MIN(4%,F6*125%) -> 0.03775 | J6: =IF(I6="","",I6-F6) | K6: =IF(I6="","Not entered",IF(I6<G6,"Below band",IF(I6>H6,"Above band","Within band"))) -> Not entered | L6: =IF(I6="","Enter actual weight",IF(I6<G6,"Review / Add",IF(I6>H6,"Review / Trim","No action"))) -> Enter actual weight | M6: Unassigned | N6: Current
A7: Strategic Anchors | B7: JNJ | C7: Johnson & Johnson | D7: Equity | E7: Healthcare and life-sciences resilience anchor | F7: 0.0302 | G7: =MAX(1%,F7*75%) -> 0.02265 | H7: =MIN(4%,F7*125%) -> 0.03775 | J7: =IF(I7="","",I7-F7) | K7: =IF(I7="","Not entered",IF(I7<G7,"Below band",IF(I7>H7,"Above band","Within band"))) -> Not entered | L7: =IF(I7="","Enter actual weight",IF(I7<G7,"Review / Add",IF(I7>H7,"Review / Trim","No action"))) -> Enter actual weight | M7: Unassigned | N7: Current
A8: Strategic Anchors | B8: MSFT | C8: Microsoft Corporation | D8: Equity | E8: Enterprise technology and AI platform anchor | F8: 0.0302 | G8: =MAX(1%,F8*75%) -> 0.02265 | H8: =MIN(4%,F8*125%) -> 0.03775 | J8: =IF(I8="","",I8-F8) | K8: =IF(I8="","Not entered",IF(I8<G8,"Below band",IF(I8>H8,"Above band","Within band"))) -> Not entered | L8: =IF(I8="","Enter actual weight",IF(I8<G8,"Review / Add",IF(I8>H8,"Review / Trim","No action"))) -> Enter actual weight | M8: Unassigned | N8: Current
A9: Strategic Anchors | B9: V | C9: Visa Inc. | D9: Equity | E9: Global payments infrastructure anchor | F9: 0.0288 | G9: =MAX(1%,F9*75%) -> 0.0216 | H9: =MIN(4%,F9*125%) -> 0.036 | J9: =IF(I9="","",I9-F9) | K9: =IF(I9="","Not entered",IF(I9<G9,"Below band",IF(I9>H9,"Above band","Within band"))) -> Not entered | L9: =IF(I9="","Enter actual weight",IF(I9<G9,"Review / Add",IF(I9>H9,"Review / Trim","No action"))) -> Enter actual weight | M9: Unassigned | N9: Current
A10: Strategic Anchors | B10: GOOGL | C10: Alphabet Inc. Class A | D10: Equity | E10: Digital platform and AI anchor | F10: 0.0284 | G10: =MAX(1%,F10*75%) -> 0.0213 | H10: =MIN(4%,F10*125%) -> 0.0355 | J10: =IF(I10="","",I10-F10) | K10: =IF(I10="","Not entered",IF(I10<G10,"Below band",IF(I10>H10,"Above band","Within band"))) -> Not entered | L10: =IF(I10="","Enter actual weight",IF(I10<G10,"Review / Add",IF(I10>H10,"Review / Trim","No action"))) -> Enter actual weight | M10: Unassigned | N10: Current
A11: Strategic Anchors | B11: MA | C11: Mastercard Incorporated | D11: Equity | E11: Global payments infrastructure anchor | F11: 0.016 | G11: =MAX(1%,F11*75%) -> 0.012 | H11: =MIN(4%,F11*125%) -> 0.02 | J11: =IF(I11="","",I11-F11) | K11: =IF(I11="","Not entered",IF(I11<G11,"Below band",IF(I11>H11,"Above band","Within band"))) -> Not entered | L11: =IF(I11="","Enter actual weight",IF(I11<G11,"Review / Add",IF(I11>H11,"Review / Trim","No action"))) -> Enter actual weight | M11: Unassigned | N11: Current
A12: Strategic Anchors | B12: AAPL | C12: Apple Inc. | D12: Equity | E12: Consumer technology ecosystem anchor | F12: 0.0156 | G12: =MAX(1%,F12*75%) -> 0.0117 | H12: =MIN(4%,F12*125%) -> 0.0195 | J12: =IF(I12="","",I12-F12) | K12: =IF(I12="","Not entered",IF(I12<G12,"Below band",IF(I12>H12,"Above band","Within band"))) -> Not entered | L12: =IF(I12="","Enter actual weight",IF(I12<G12,"Review / Add",IF(I12>H12,"Review / Trim","No action"))) -> Enter actual weight | M12: Unassigned | N12: Current
A13: Strategic Anchors | B13: AMZN | C13: Amazon.com, Inc. | D13: Equity | E13: Cloud, commerce and logistics anchor | F13: 0.0155 | G13: =MAX(1%,F13*75%) -> 0.011625 | H13: =MIN(4%,F13*125%) -> 0.019375 | J13: =IF(I13="","",I13-F13) | K13: =IF(I13="","Not entered",IF(I13<G13,"Below band",IF(I13>H13,"Above band","Within band"))) -> Not entered | L13: =IF(I13="","Enter actual weight",IF(I13<G13,"Review / Add",IF(I13>H13,"Review / Trim","No action"))) -> Enter actual weight | M13: Unassigned | N13: Current
A14: Growth Compounders | B14: AVGO | C14: Broadcom Inc. | D14: Equity | E14: Semiconductor and infrastructure-software compounder | F14: 0.0302 | G14: =MAX(1%,F14*75%) -> 0.02265 | H14: =MIN(4%,F14*125%) -> 0.03775 | J14: =IF(I14="","",I14-F14) | K14: =IF(I14="","Not entered",IF(I14<G14,"Below band",IF(I14>H14,"Above band","Within band"))) -> Not entered | L14: =IF(I14="","Enter actual weight",IF(I14<G14,"Review / Add",IF(I14>H14,"Review / Trim","No action"))) -> Enter actual weight | M14: Unassigned | N14: Current
A15: Growth Compounders | B15: LLY | C15: Eli Lilly and Company | D15: Equity | E15: Healthcare innovation compounder | F15: 0.0302 | G15: =MAX(1%,F15*75%) -> 0.02265 | H15: =MIN(4%,F15*125%) -> 0.03775 | J15: =IF(I15="","",I15-F15) | K15: =IF(I15="","Not entered",IF(I15<G15,"Below band",IF(I15>H15,"Above band","Within band"))) -> Not entered | L15: =IF(I15="","Enter actual weight",IF(I15<G15,"Review / Add",IF(I15>H15,"Review / Trim","No action"))) -> Enter actual weight | M15: Unassigned | N15: Current
A16: Growth Compounders | B16: NVDA | C16: NVIDIA Corporation | D16: Equity | E16: AI compute growth engine | F16: 0.0268 | G16: =MAX(1%,F16*75%) -> 0.0201 | H16: =MIN(4%,F16*125%) -> 0.0335 | J16: =IF(I16="","",I16-F16) | K16: =IF(I16="","Not entered",IF(I16<G16,"Below band",IF(I16>H16,"Above band","Within band"))) -> Not entered | L16: =IF(I16="","Enter actual weight",IF(I16<G16,"Review / Add",IF(I16>H16,"Review / Trim","No action"))) -> Enter actual weight | M16: Unassigned | N16: Current
... A51: Income & Risk Management | B51: PFF | C51: iShares Preferred and Income Securities ETF | D51: ETF | E51: Preferred securities income diversification | F51: 0.0302 | G51: =MAX(1%,F51*75%) -> 0.02265 | H51: =MIN(4%,F51*125%) -> 0.03775 | J51: =IF(I51="","",I51-F51) | K51: =IF(I51="","Not entered",IF(I51<G51,"Below band",IF(I51>H51,"Above band","Within band"))) -> Not entered | L51: =IF(I51="","Enter actual weight",IF(I51<G51,"Review / Add",IF(I51>H51,"Review / Trim","No action"))) -> Enter actual weight | M51: Unassigned | N51: Current
A53: PORTFOLIO TOTAL | F53: =SUM(F5:F51) -> 1 | I53: =SUM(I5:I51) -> 0 | J53: =I53-F53 -> -1 | K53: =IF(ABS(F53-100%)<0.000001,"Certified 100.00%","ERROR") -> Certified 100.00%

Sheet Sleeve Summary
A1: MFPDF v1.0 — Sleeve Allocation Summary
A3: Production Sleeve | B3: Positions | C3: Equities | D3: ETFs | E3: Target Allocation | F3: Share of Portfolio
A4: Strategic Anchors | B4: =COUNTIF('Certified Allocation'!$A$5:$A$51,A4) -> 9 | C4: =COUNTIFS('Certified Allocation'!$A$5:$A$51,A4,'Certified Allocation'!$D$5:$D$51,"Equity") -> 9 | D4: =COUNTIFS('Certified Allocation'!$A$5:$A$51,A4,'Certified Allocation'!$D$5:$D$51,"ETF") -> 0 | E4: =SUMIF('Certified Allocation'!$A$5:$A$51,A4,'Certified Allocation'!$F$5:$F$51) -> 0.2251 | F4: =E4 -> 0.2251
A5: Growth Compounders | B5: =COUNTIF('Certified Allocation'!$A$5:$A$51,A5) -> 6 | C5: =COUNTIFS('Certified Allocation'!$A$5:$A$51,A5,'Certified Allocation'!$D$5:$D$51,"Equity") -> 6 | D5: =COUNTIFS('Certified Allocation'!$A$5:$A$51,A5,'Certified Allocation'!$D$5:$D$51,"ETF") -> 0 | E5: =SUMIF('Certified Allocation'!$A$5:$A$51,A5,'Certified Allocation'!$F$5:$F$51) -> 0.1339 | F5: =E5 -> 0.1339
A6: Digital Infrastructure & AI | B6: =COUNTIF('Certified Allocation'!$A$5:$A$51,A6) -> 8 | C6: =COUNTIFS('Certified Allocation'!$A$5:$A$51,A6,'Certified Allocation'!$D$5:$D$51,"Equity") -> 8 | D6: =COUNTIFS('Certified Allocation'!$A$5:$A$51,A6,'Certified Allocation'!$D$5:$D$51,"ETF") -> 0 | E6: =SUMIF('Certified Allocation'!$A$5:$A$51,A6,'Certified Allocation'!$F$5:$F$51) -> 0.129 | F6: =E6 -> 0.129
A7: Industrials & Infrastructure | B7: =COUNTIF('Certified Allocation'!$A$5:$A$51,A7) -> 9 | C7: =COUNTIFS('Certified Allocation'!$A$5:$A$51,A7,'Certified Allocation'!$D$5:$D$51,"Equity") -> 9 | D7: =COUNTIFS('Certified Allocation'!$A$5:$A$51,A7,'Certified Allocation'!$D$5:$D$51,"ETF") -> 0 | E7: =SUMIF('Certified Allocation'!$A$5:$A$51,A7,'Certified Allocation'!$F$5:$F$51) -> 0.1711 | F7: =E7 -> 0.1711
A8: Financial Infrastructure | B8: =COUNTIF('Certified Allocation'!$A$5:$A$51,A8) -> 5 | C8: =COUNTIFS('Certified Allocation'!$A$5:$A$51,A8,'Certified Allocation'!$D$5:$D$51,"Equity") -> 4 | D8: =COUNTIFS('Certified Allocation'!$A$5:$A$51,A8,'Certified Allocation'!$D$5:$D$51,"ETF") -> 1 | E8: =SUMIF('Certified Allocation'!$A$5:$A$51,A8,'Certified Allocation'!$F$5:$F$51) -> 0.097 | F8: =E8 -> 0.097
A9: Healthcare Leadership | B9: =COUNTIF('Certified Allocation'!$A$5:$A$51,A9) -> 2 | C9: =COUNTIFS('Certified Allocation'!$A$5:$A$51,A9,'Certified Allocation'!$D$5:$D$51,"Equity") -> 1 | D9: =COUNTIFS('Certified Allocation'!$A$5:$A$51,A9,'Certified Allocation'!$D$5:$D$51,"ETF") -> 1 | E9: =SUMIF('Certified Allocation'!$A$5:$A$51,A9,'Certified Allocation'!$F$5:$F$51) -> 0.0361 | F9: =E9 -> 0.0361
A10: Energy & Natural Resources | B10: =COUNTIF('Certified Allocation'!$A$5:$A$51,A10) -> 5 | C10: =COUNTIFS('Certified Allocation'!$A$5:$A$51,A10,'Certified Allocation'!$D$5:$D$51,"Equity") -> 3 | D10: =COUNTIFS('Certified Allocation'!$A$5:$A$51,A10,'Certified Allocation'!$D$5:$D$51,"ETF") -> 2 | E10: =SUMIF('Certified Allocation'!$A$5:$A$51,A10,'Certified Allocation'!$F$5:$F$51) -> 0.1172 | F10: =E10 -> 0.1172
A11: Income & Risk Management | B11: =COUNTIF('Certified Allocation'!$A$5:$A$51,A11) -> 3 | C11: =COUNTIFS('Certified Allocation'!$A$5:$A$51,A11,'Certified Allocation'!$D$5:$D$51,"Equity") -> 0 | D11: =COUNTIFS('Certified Allocation'!$A$5:$A$51,A11,'Certified Allocation'!$D$5:$D$51,"ETF") -> 3 | E11: =SUMIF('Certified Allocation'!$A$5:$A$51,A11,'Certified Allocation'!$F$5:$F$51) -> 0.0906 | F11: =E11 -> 0.0906
A12: TOTAL | B12: =SUM(B4:B11) -> 47 | C12: =SUM(C4:C11) -> 40 | D12: =SUM(D4:D11) -> 7 | E12: =SUM(E4:E11) -> 1 | F12: =SUM(F4:F11) -> 1

Sheet Rebalancing
A1: MFPDF v1.0 — Rebalancing Control Framework
A3: Control | B3: Definition | C3: Formula / Trigger | D3: Required Action | E3: Authority | F3: Frequency | G3: Status
A4: Target weight | B4: Certified strategic allocation for each holding | C4: Certified Allocation column F | D4: Benchmark actual portfolio | E4: MFPDF v1.0 | F4: Continuous | G4: Active
A5: Lower band | B5: 75% of target, floored at 1.00% | C5: MAX(1%, Target × 75%) | D5: Review potential add | E5: Stewardship Committee | F5: When breached | G5: Active
A6: Upper band | B6: 125% of target, capped at 4.00% | C6: MIN(4%, Target × 125%) | D6: Review potential trim | E6: Stewardship Committee | F6: When breached | G6: Active
A7: Actual weight | B7: Current account/model weight | C7: User-entered in column I | D7: Update before review | E7: Portfolio Operations | F7: Weekly / as needed | G7: Input required
A8: Automatic trading | B8: Not authorized | C8: No automatic execution | D8: Committee review required | E8: Stewardship Committee | F8: As needed | G8: Prohibited
A9: Scheduled review | B9: Portfolio-level reconciliation | C9: Quarterly plus material-event review | D9: Rebalance only when justified | E9: Stewardship Committee | F9: Quarterly | G9: Active

Sheet Sources & Certification
A1: Sources, Reconciliation Record & Certification
A3: Source / Record | B3: Use | C3: Key Finding | D3: Disposition | E3: Reference | F3: Status
A4: MQOC-005 Portfolio B YCharts Export | B4: Canonical constituent list | C4: 47 symbols including MMC | D4: Adopted as Portfolio B constituent control | E4: ChatGPT Library: MQOC-005_Portfolio_B_YCharts_Export.csv | F4: Certified
A5: MQOC-006 Provisional Optimized Portfolio Weights | B5: Empirical target weights | C5: 46 named positions + 2.00% placeholder | D5: Placeholder reconciled to MMC; all other weights unchanged | E5: ChatGPT Library: MQOC-006_Provisional_Optimized_Portfolio_Weights.xlsx | F5: Reconciled
A6: Prior allocation workbook | B6: Preliminary 56-position ranges | C6: Different draft portfolio; not Portfolio B | D6: Declared obsolete and superseded | E6: Manifest_Flagship_Portfolio_V1_0_Allocation_Schedule.xlsx | F6: Obsolete
A7: Position count reconciliation | B7: Constituent classification | C7: 40 equities + 7 ETFs = 47 positions | D7: Workbook reflects actual Portfolio B export | E7: Certified Allocation sheet | F7: Verified
A8: Weight reconciliation | B8: Portfolio total | C8: 100.00% after MMC substitution | D8: No residual or unallocated cash | E8: Certified Allocation total | F8: Verified
A9: Certification date | B9: Founders Edition operational record | C9: 46223 | D9: Effective upon publication | E9: MPEC / MFPDF record | F9: Certified
A11: Certification Statement
A12: Portfolio B is designated as the sole canonical Manifest Flagship Portfolio implementation. This workbook is the authoritative MFPDF Founders Edition v1.0 target allocation schedule for MWIR benchmarking, stewardship review, optimization, Monte Carlo analysis, performance attribution and institutional publication.
A15: MOPS-002 Workspace Certification
A16: Resolution | B16: Use | C16: Certified Scope | D16: Disposition | E16: Reference | F16: Status
A17: MOPS-002-FR-001 | B17: Workspace architecture certification | C17: PEW-001 through PEW-007, control principles and workflow | D17: Adopted, certified and frozen effective July 26, 2026 | E17: 15 MOPS-002 Freeze Record | F17: Certified & Frozen
A19: Workspace certification does not certify a portfolio scenario, a trade, or a new MFPDF issuance. The existing certified Portfolio B allocation remains unchanged.
A20: MOPS-003 Research Command Center — Construction Record
A21: Resolution / Module | B21: Use | C21: Installed Scope | D21: Disposition | E21: Reference | F21: Status
A22: MOPS-003 / RCC-001 | B22: Executive research command view | C22: Research readiness, exception queue, module roadmap and referrals | D22: Installed as construction candidate | E22: 16 RCC-001 Control Center | F22: Active — Installed
A23: MOPS-003 / RCC-002 | B23: Research intake and chain-of-evidence control | C23: Evidence ledger, verification, materiality, routing and referral gates | D23: Installed as construction candidate | E23: 17 RCC-002 Control Center / 18 RCC-002 Evidence Ledger | F23: Active — Installed
A24: MOPS-003 / RCC-003 | B24: MIAR dossier identity, freshness and review control | C24: 47-holding MIAR registry, review log, scores, cadence, exception controls and RCC-007 referral state | D24: Installed as construction candidate | E24: 19 RCC-003 Control Center / 20 RCC-003 MIAR Registry / 21 RCC-003 MIAR Review Log | F24: Active — Installed
A25: MOPS-003 / RCC-004 | B25: MASR registry, candidate stage-gate and PEW referral control | C25: 150-slot controlled MASR registry, 47 certified holdings seeded, 200-row candidate pipeline, eligibility and exception gates, committee disposition and PEW-004 linkage | D25: Installed as construction candidate | E25: 22 RCC-004 Control Center / 23 RCC-004 MASR Registry / 24 RCC-004 Candidate Pipeline | F25: Active — Installed
A26: MOPS-003 remains in construction and is not frozen. RCC-001 through RCC-004 certify neither a research conclusion nor a portfolio action. They create an auditable evidence-to-dossier-to-registry-to-candidate control path while preserving the certified MFPDF as the sole portfolio system of record.

Sheet 99 Dashboard Data
A1: Sleeve | B1: Target | C1: Actual | D1: Variance | R1: Rank | S1: Symbol | T1: Security | U1: Weight | V1: Portfolio Role | W1: Conviction
A2: ='Sleeve Summary'!A4 -> Strategic Anchors | B2: ='Sleeve Summary'!E4 -> 0.2251 | C2: =IF($B$61=0,SUMIF('Certified Allocation'!$A$5:$A$51,A2,'Certified Allocation'!$I$5:$I$51),0) -> 0 | D2: =C2-B2 -> -0.2251 | R2: 1 | S2: =IFERROR(INDEX($B$12:$B$58,MATCH(R2,$H$12:$H$58,0)),"") -> BRK.B | T2: =IFERROR(INDEX($C$12:$C$58,MATCH(R2,$H$12:$H$58,0)),"") -> Berkshire Hathaway Inc. Class B | U2: =IFERROR(INDEX($G$12:$G$58,MATCH(R2,$H$12:$H$58,0)),"") -> 0.0302 | V2: =IFERROR(INDEX($I$12:$I$58,MATCH(R2,$H$12:$H$58,0)),"") -> Diversified capital-allocation anchor | W2: =IFERROR(INDEX($J$12:$J$58,MATCH(R2,$H$12:$H$58,0)),"") -> Unassigned
A3: ='Sleeve Summary'!A5 -> Growth Compounders | B3: ='Sleeve Summary'!E5 -> 0.1339 | C3: =IF($B$61=0,SUMIF('Certified Allocation'!$A$5:$A$51,A3,'Certified Allocation'!$I$5:$I$51),0) -> 0 | D3: =C3-B3 -> -0.1339 | R3: 2 | S3: =IFERROR(INDEX($B$12:$B$58,MATCH(R3,$H$12:$H$58,0)),"") -> COST | T3: =IFERROR(INDEX($C$12:$C$58,MATCH(R3,$H$12:$H$58,0)),"") -> Costco Wholesale Corporation | U3: =IFERROR(INDEX($G$12:$G$58,MATCH(R3,$H$12:$H$58,0)),"") -> 0.0302 | V3: =IFERROR(INDEX($I$12:$I$58,MATCH(R3,$H$12:$H$58,0)),"") -> Consumer-resilience anchor | W3: =IFERROR(INDEX($J$12:$J$58,MATCH(R3,$H$12:$H$58,0)),"") -> Unassigned
A4: ='Sleeve Summary'!A6 -> Digital Infrastructure & AI | B4: ='Sleeve Summary'!E6 -> 0.129 | C4: =IF($B$61=0,SUMIF('Certified Allocation'!$A$5:$A$51,A4,'Certified Allocation'!$I$5:$I$51),0) -> 0 | D4: =C4-B4 -> -0.129 | R4: 3 | S4: =IFERROR(INDEX($B$12:$B$58,MATCH(R4,$H$12:$H$58,0)),"") -> JNJ | T4: =IFERROR(INDEX($C$12:$C$58,MATCH(R4,$H$12:$H$58,0)),"") -> Johnson & Johnson | U4: =IFERROR(INDEX($G$12:$G$58,MATCH(R4,$H$12:$H$58,0)),"") -> 0.0302 | V4: =IFERROR(INDEX($I$12:$I$58,MATCH(R4,$H$12:$H$58,0)),"") -> Healthcare and life-sciences resilience anchor | W4: =IFERROR(INDEX($J$12:$J$58,MATCH(R4,$H$12:$H$58,0)),"") -> Unassigned
A5: ='Sleeve Summary'!A7 -> Industrials & Infrastructure | B5: ='Sleeve Summary'!E7 -> 0.1711 | C5: =IF($B$61=0,SUMIF('Certified Allocation'!$A$5:$A$51,A5,'Certified Allocation'!$I$5:$I$51),0) -> 0 | D5: =C5-B5 -> -0.1711 | R5: 4 | S5: =IFERROR(INDEX($B$12:$B$58,MATCH(R5,$H$12:$H$58,0)),"") -> MSFT | T5: =IFERROR(INDEX($C$12:$C$58,MATCH(R5,$H$12:$H$58,0)),"") -> Microsoft Corporation | U5: =IFERROR(INDEX($G$12:$G$58,MATCH(R5,$H$12:$H$58,0)),"") -> 0.0302 | V5: =IFERROR(INDEX($I$12:$I$58,MATCH(R5,$H$12:$H$58,0)),"") -> Enterprise technology and AI platform anchor | W5: =IFERROR(INDEX($J$12:$J$58,MATCH(R5,$H$12:$H$58,0)),"") -> Unassigned
A6: ='Sleeve Summary'!A8 -> Financial Infrastructure | B6: ='Sleeve Summary'!E8 -> 0.097 | C6: =IF($B$61=0,SUMIF('Certified Allocation'!$A$5:$A$51,A6,'Certified Allocation'!$I$5:$I$51),0) -> 0 | D6: =C6-B6 -> -0.097 | R6: 5 | S6: =IFERROR(INDEX($B$12:$B$58,MATCH(R6,$H$12:$H$58,0)),"") -> AVGO | T6: =IFERROR(INDEX($C$12:$C$58,MATCH(R6,$H$12:$H$58,0)),"") -> Broadcom Inc. | U6: =IFERROR(INDEX($G$12:$G$58,MATCH(R6,$H$12:$H$58,0)),"") -> 0.0302 | V6: =IFERROR(INDEX($I$12:$I$58,MATCH(R6,$H$12:$H$58,0)),"") -> Semiconductor and infrastructure-software compounder | W6: =IFERROR(INDEX($J$12:$J$58,MATCH(R6,$H$12:$H$58,0)),"") -> Unassigned
A7: ='Sleeve Summary'!A9 -> Healthcare Leadership | B7: ='Sleeve Summary'!E9 -> 0.0361 | C7: =IF($B$61=0,SUMIF('Certified Allocation'!$A$5:$A$51,A7,'Certified Allocation'!$I$5:$I$51),0) -> 0 | D7: =C7-B7 -> -0.0361 | R7: 6 | S7: =IFERROR(INDEX($B$12:$B$58,MATCH(R7,$H$12:$H$58,0)),"") -> LLY | T7: =IFERROR(INDEX($C$12:$C$58,MATCH(R7,$H$12:$H$58,0)),"") -> Eli Lilly and Company | U7: =IFERROR(INDEX($G$12:$G$58,MATCH(R7,$H$12:$H$58,0)),"") -> 0.0302 | V7: =IFERROR(INDEX($I$12:$I$58,MATCH(R7,$H$12:$H$58,0)),"") -> Healthcare innovation compounder | W7: =IFERROR(INDEX($J$12:$J$58,MATCH(R7,$H$12:$H$58,0)),"") -> Unassigned
A8: ='Sleeve Summary'!A10 -> Energy & Natural Resources | B8: ='Sleeve Summary'!E10 -> 0.1172 | C8: =IF($B$61=0,SUMIF('Certified Allocation'!$A$5:$A$51,A8,'Certified Allocation'!$I$5:$I$51),0) -> 0 | D8: =C8-B8 -> -0.1172 | R8: 7 | S8: =IFERROR(INDEX($B$12:$B$58,MATCH(R8,$H$12:$H$58,0)),"") -> CME | T8: =IFERROR(INDEX($C$12:$C$58,MATCH(R8,$H$12:$H$58,0)),"") -> CME Group Inc. | U8: =IFERROR(INDEX($G$12:$G$58,MATCH(R8,$H$12:$H$58,0)),"") -> 0.0302 | V8: =IFERROR(INDEX($I$12:$I$58,MATCH(R8,$H$12:$H$58,0)),"") -> Market infrastructure and derivatives exchange | W8: =IFERROR(INDEX($J$12:$J$58,MATCH(R8,$H$12:$H$58,0)),"") -> Unassigned
A9: ='Sleeve Summary'!A11 -> Income & Risk Management | B9: ='Sleeve Summary'!E11 -> 0.0906 | C9: =IF($B$61=0,SUMIF('Certified Allocation'!$A$5:$A$51,A9,'Certified Allocation'!$I$5:$I$51),0) -> 0 | D9: =C9-B9 -> -0.0906 | R9: 8 | S9: =IFERROR(INDEX($B$12:$B$58,MATCH(R9,$H$12:$H$58,0)),"") -> LNG | T9: =IFERROR(INDEX($C$12:$C$58,MATCH(R9,$H$12:$H$58,0)),"") -> Cheniere Energy, Inc. | U9: =IFERROR(INDEX($G$12:$G$58,MATCH(R9,$H$12:$H$58,0)),"") -> 0.0302 | V9: =IFERROR(INDEX($I$12:$I$58,MATCH(R9,$H$12:$H$58,0)),"") -> LNG export infrastructure | W9: =IFERROR(INDEX($J$12:$J$58,MATCH(R9,$H$12:$H$58,0)),"") -> Unassigned
R10: 9 | S10: =IFERROR(INDEX($B$12:$B$58,MATCH(R10,$H$12:$H$58,0)),"") -> VPU | T10: =IFERROR(INDEX($C$12:$C$58,MATCH(R10,$H$12:$H$58,0)),"") -> Vanguard Utilities ETF | U10: =IFERROR(INDEX($G$12:$G$58,MATCH(R10,$H$12:$H$58,0)),"") -> 0.0302 | V10: =IFERROR(INDEX($I$12:$I$58,MATCH(R10,$H$12:$H$58,0)),"") -> Utilities and defensive infrastructure ETF | W10: =IFERROR(INDEX($J$12:$J$58,MATCH(R10,$H$12:$H$58,0)),"") -> Unassigned
A11: Source Row | B11: Symbol | C11: Security | D11: Sleeve | E11: Target | F11: Actual | G11: Ranking Weight | H11: Rank | I11: Portfolio Role | J11: Conviction | K11: Lower | L11: Upper | M11: Band Status | N11: Action | O11: Alert Score | P11: Alert Rank | R11: 10 | S11: =IFERROR(INDEX($B$12:$B$58,MATCH(R11,$H$12:$H$58,0)),"") -> JEPI | T11: =IFERROR(INDEX($C$12:$C$58,MATCH(R11,$H$12:$H$58,0)),"") -> JPMorgan Equity Premium Income ETF | U11: =IFERROR(INDEX($G$12:$G$58,MATCH(R11,$H$12:$H$58,0)),"") -> 0.0302 | V11: =IFERROR(INDEX($I$12:$I$58,MATCH(R11,$H$12:$H$58,0)),"") -> Diversified equity income and volatility moderation | W11: =IFERROR(INDEX($J$12:$J$58,MATCH(R11,$H$12:$H$58,0)),"") -> Unassigned
A12: 5 | B12: ='Certified Allocation'!B5 -> BRK.B | C12: ='Certified Allocation'!C5 -> Berkshire Hathaway Inc. Class B | D12: ='Certified Allocation'!A5 -> Strategic Anchors | E12: ='Certified Allocation'!F5 -> 0.0302 | F12: ='Certified Allocation'!I5 -> 0 | G12: =IF($B$61=0,F12,E12) -> 0.0302 | H12: =RANK(G12,$G$12:$G$58,0)+COUNTIF($G$12:G12,G12)-1 -> 1 | I12: ='Certified Allocation'!E5 -> Diversified capital-allocation anchor | J12: ='Certified Allocation'!M5 -> Unassigned | K12: ='Certified Allocation'!G5 -> 0.02265 | L12: ='Certified Allocation'!H5 -> 0.03775 | M12: ='Certified Allocation'!K5 -> Not entered | N12: ='Certified Allocation'!L5 -> Enter actual weight | O12: =IF(F12="",0,IF(OR(F12<K12,F12>L12),ABS(F12-E12),0)) -> 0.0302 | P12: =IF(O12=0,"",RANK(O12,$O$12:$O$58,0)+COUNTIF($O$12:O12,O12)-1) -> 1
A13: 6 | B13: ='Certified Allocation'!B6 -> COST | C13: ='Certified Allocation'!C6 -> Costco Wholesale Corporation | D13: ='Certified Allocation'!A6 -> Strategic Anchors | E13: ='Certified Allocation'!F6 -> 0.0302 | F13: ='Certified Allocation'!I6 -> 0 | G13: =IF($B$61=0,F13,E13) -> 0.0302 | H13: =RANK(G13,$G$12:$G$58,0)+COUNTIF($G$12:G13,G13)-1 -> 2 | I13: ='Certified Allocation'!E6 -> Consumer-resilience anchor | J13: ='Certified Allocation'!M6 -> Unassigned | K13: ='Certified Allocation'!G6 -> 0.02265 | L13: ='Certified Allocation'!H6 -> 0.03775 | M13: ='Certified Allocation'!K6 -> Not entered | N13: ='Certified Allocation'!L6 -> Enter actual weight | O13: =IF(F13="",0,IF(OR(F13<K13,F13>L13),ABS(F13-E13),0)) -> 0.0302 | P13: =IF(O13=0,"",RANK(O13,$O$12:$O$58,0)+COUNTIF($O$12:O13,O13)-1) -> 2
A14: 7 | B14: ='Certified Allocation'!B7 -> JNJ | C14: ='Certified Allocation'!C7 -> Johnson & Johnson | D14: ='Certified Allocation'!A7 -> Strategic Anchors | E14: ='Certified Allocation'!F7 -> 0.0302 | F14: ='Certified Allocation'!I7 -> 0 | G14: =IF($B$61=0,F14,E14) -> 0.0302 | H14: =RANK(G14,$G$12:$G$58,0)+COUNTIF($G$12:G14,G14)-1 -> 3 | I14: ='Certified Allocation'!E7 -> Healthcare and life-sciences resilience anchor | J14: ='Certified Allocation'!M7 -> Unassigned | K14: ='Certified Allocation'!G7 -> 0.02265 | L14: ='Certified Allocation'!H7 -> 0.03775 | M14: ='Certified Allocation'!K7 -> Not entered | N14: ='Certified Allocation'!L7 -> Enter actual weight | O14: =IF(F14="",0,IF(OR(F14<K14,F14>L14),ABS(F14-E14),0)) -> 0.0302 | P14: =IF(O14=0,"",RANK(O14,$O$12:$O$58,0)+COUNTIF($O$12:O14,O14)-1) -> 3 | R14: Rank | S14: Symbol | T14: Actual | U14: Target | V14: Variance | W14: Band Status | X14: Action
A15: 8 | B15: ='Certified Allocation'!B8 -> MSFT | C15: ='Certified Allocation'!C8 -> Microsoft Corporation | D15: ='Certified Allocation'!A8 -> Strategic Anchors | E15: ='Certified Allocation'!F8 -> 0.0302 | F15: ='Certified Allocation'!I8 -> 0 | G15: =IF($B$61=0,F15,E15) -> 0.0302 | H15: =RANK(G15,$G$12:$G$58,0)+COUNTIF($G$12:G15,G15)-1 -> 4 | I15: ='Certified Allocation'!E8 -> Enterprise technology and AI platform anchor | J15: ='Certified Allocation'!M8 -> Unassigned | K15: ='Certified Allocation'!G8 -> 0.02265 | L15: ='Certified Allocation'!H8 -> 0.03775 | M15: ='Certified Allocation'!K8 -> Not entered | N15: ='Certified Allocation'!L8 -> Enter actual weight | O15: =IF(F15="",0,IF(OR(F15<K15,F15>L15),ABS(F15-E15),0)) -> 0.0302 | P15: =IF(O15=0,"",RANK(O15,$O$12:$O$58,0)+COUNTIF($O$12:O15,O15)-1) -> 4 | R15: 1 | S15: =IFERROR(INDEX($B$12:$B$58,MATCH(R15,$P$12:$P$58,0)),"") -> BRK.B | T15: =IF(S15="","",INDEX($F$12:$F$58,MATCH(R15,$P$12:$P$58,0))) -> 0 | U15: =IF(S15="","",INDEX($E$12:$E$58,MATCH(R15,$P$12:$P$58,0))) -> 0.0302 | V15: =IF(S15="","",T15-U15) -> -0.0302 | W15: =IF(S15="","",INDEX($M$12:$M$58,MATCH(R15,$P$12:$P$58,0))) -> Not entered | X15: =IF(S15="","",INDEX($N$12:$N$58,MATCH(R15,$P$12:$P$58,0))) -> Enter actual weight
